default-hostname
*** Reading remote logs from Cloud Logging.
[2025-05-16, 17:59:21 UTC] {local_task_job_runner.py:123} ▶ Pre task execution logs
[2025-05-16, 17:59:22 UTC] {connection.py:277} WARNING - Connection schemes (type: google_cloud_platform) shall not contain '_' according to RFC3986.
[2025-05-16, 17:59:22 UTC] {base.py:84} INFO - Retrieving connection '***'
[2025-05-16, 17:59:22 UTC] {logging_mixin.py:190} INFO - Attempt 1 of 2
[2025-05-16, 17:59:22 UTC] {logging_mixin.py:190} INFO - Executing query for fjpv:

            SELECT COUNT(*) AS row_cnt
            FROM vz-it-pr-fjpv-mlopdo-0.mlops_curated_tbls_rd_v.run_dt_cntrl_tbl_v2
            WHERE process_nm in ('ETL_NTWK_DMA_NQES_SITE')
            AND status = 'COMPLETE'
            AND run_dt = '2025-04-30'
        
[2025-05-16, 17:59:22 UTC] {logging_mixin.py:190} INFO - Executing query: 
            SELECT COUNT(*) AS row_cnt
            FROM vz-it-pr-fjpv-mlopdo-0.mlops_curated_tbls_rd_v.run_dt_cntrl_tbl_v2
            WHERE process_nm in ('ETL_NTWK_DMA_NQES_SITE')
            AND status = 'COMPLETE'
            AND run_dt = '2025-04-30'
        
[2025-05-16, 17:59:22 UTC] {sql.py:553} INFO - Running statement: 
            SELECT COUNT(*) AS row_cnt
            FROM vz-it-pr-fjpv-mlopdo-0.mlops_curated_tbls_rd_v.run_dt_cntrl_tbl_v2
            WHERE process_nm in ('ETL_NTWK_DMA_NQES_SITE')
            AND status = 'COMPLETE'
            AND run_dt = '2025-04-30'
        , parameters: None
[2025-05-16, 17:59:22 UTC] {bigquery.py:1699} INFO - Inserting job airflow_1747418362523536_cbae9f9aaced25602ae10d2404e1a8e9
[2025-05-16, 17:59:22 UTC] {logging_mixin.py:190} INFO - Error executing query for fjpv: 400 Encountered " "-" "- "" at line 3, column 20.
Was expecting:
    <EOF>
[Try using standard SQL (https://cloud.google.com/bigquery/docs/reference/standard-sql/enabling-standard-sql)]; reason: invalidQuery, location: query, message: Encountered " "-" "- "" at line 3, column 20.
Was expecting:
    <EOF>
[Try using standard SQL (https://cloud.google.com/bigquery/docs/reference/standard-sql/enabling-standard-sql)]

Location: us-east4
Job ID: airflow_1747418362523536_cbae9f9aaced25602ae10d2404e1a8e9
[2025-05-16, 17:59:22 UTC] {logging_mixin.py:190} INFO - Data not available, retrying in 3 minutes...
[2025-05-16, 18:02:22 UTC] {logging_mixin.py:190} INFO - Attempt 2 of 2
[2025-05-16, 18:02:22 UTC] {logging_mixin.py:190} INFO - Executing query for fjpv:

            SELECT COUNT(*) AS row_cnt
            FROM vz-it-pr-fjpv-mlopdo-0.mlops_curated_tbls_rd_v.run_dt_cntrl_tbl_v2
            WHERE process_nm in ('ETL_NTWK_DMA_NQES_SITE')
            AND status = 'COMPLETE'
            AND run_dt = '2025-04-30'
        
[2025-05-16, 18:02:22 UTC] {logging_mixin.py:190} INFO - Executing query: 
            SELECT COUNT(*) AS row_cnt
            FROM vz-it-pr-fjpv-mlopdo-0.mlops_curated_tbls_rd_v.run_dt_cntrl_tbl_v2
            WHERE process_nm in ('ETL_NTWK_DMA_NQES_SITE')
            AND status = 'COMPLETE'
            AND run_dt = '2025-04-30'
        
[2025-05-16, 18:02:22 UTC] {sql.py:553} INFO - Running statement: 
            SELECT COUNT(*) AS row_cnt
            FROM vz-it-pr-fjpv-mlopdo-0.mlops_curated_tbls_rd_v.run_dt_cntrl_tbl_v2
            WHERE process_nm in ('ETL_NTWK_DMA_NQES_SITE')
            AND status = 'COMPLETE'
            AND run_dt = '2025-04-30'
        , parameters: None
[2025-05-16, 18:02:22 UTC] {bigquery.py:1699} INFO - Inserting job airflow_1747418542831627_cbae9f9aaced25602ae10d2404e1a8e9
[2025-05-16, 18:02:22 UTC] {logging_mixin.py:190} INFO - Error executing query for fjpv: 400 Encountered " "-" "- "" at line 3, column 20.
Was expecting:
    <EOF>
[Try using standard SQL (https://cloud.google.com/bigquery/docs/reference/standard-sql/enabling-standard-sql)]; reason: invalidQuery, location: query, message: Encountered " "-" "- "" at line 3, column 20.
Was expecting:
    <EOF>
[Try using standard SQL (https://cloud.google.com/bigquery/docs/reference/standard-sql/enabling-standard-sql)]

Location: us-east4
Job ID: airflow_1747418542831627_cbae9f9aaced25602ae10d2404e1a8e9
[2025-05-16, 18:02:22 UTC] {logging_mixin.py:190} INFO - Data not available, retrying in 3 minutes...
[2025-05-16, 18:05:23 UTC] {taskinstance.py:3312} ERROR - Task failed with exception
Traceback (most recent call last):
  File "/opt/python3.11/lib/python3.11/site-packages/airflow/models/taskinstance.py", line 768, in _execute_task
    result = _execute_callable(context=context, **execute_callable_kwargs)
             ^^^^^^^^^^^^^^^^^^^^^^^^^^^^^^^^^^^^^^^^^^^^^^^^^^^^^^^^^^^^^
  File "/opt/python3.11/lib/python3.11/site-packages/airflow/models/taskinstance.py", line 734, in _execute_callable
    return ExecutionCallableRunner(
           ^^^^^^^^^^^^^^^^^^^^^^^^
  File "/opt/python3.11/lib/python3.11/site-packages/airflow/utils/operator_helpers.py", line 252, in run
    return self.func(*args, **kwargs)
           ^^^^^^^^^^^^^^^^^^^^^^^^^^
  File "/opt/python3.11/lib/python3.11/site-packages/airflow/models/baseoperator.py", line 415, in wrapper
    return func(self, *args, **kwargs)
           ^^^^^^^^^^^^^^^^^^^^^^^^^^^
  File "/opt/python3.11/lib/python3.11/site-packages/airflow/operators/python.py", line 238, in execute
    return_value = self.execute_callable()
                   ^^^^^^^^^^^^^^^^^^^^^^^
  File "/opt/python3.11/lib/python3.11/site-packages/airflow/operators/python.py", line 256, in execute_callable
    return runner.run(*self.op_args, **self.op_kwargs)
           ^^^^^^^^^^^^^^^^^^^^^^^^^^^^^^^^^^^^^^^^^^^
  File "/opt/python3.11/lib/python3.11/site-packages/airflow/utils/operator_helpers.py", line 252, in run
    return self.func(*args, **kwargs)
           ^^^^^^^^^^^^^^^^^^^^^^^^^^
  File "/home/airflow/gcs/dags/vz-it-gudv-dtwndo-0/nqes_site/python/gudv_nqes_site.py", line 172, in check_src_data
    raise AirflowException("Source data not available after retries. Failing DAG execution.")
airflow.exceptions.AirflowException: Source data not available after retries. Failing DAG execution.
[2025-05-16, 18:05:23 UTC] {taskinstance.py:1226} INFO - Marking task as FAILED. dag_id=gudv_nw_research_assistant_nqes_site_daily_norm, task_id=source_data_check, run_id=scheduled__2025-04-30T19:30:00+00:00, execution_date=20250430T193000, start_date=20250516T175921, end_date=20250516T180523
[2025-05-16, 18:05:23 UTC] {warnings.py:110} WARNING - /opt/python3.11/lib/python3.11/site-packages/airflow/utils/email.py:155: RemovedInAirflow3Warning: Fetching SMTP credentials from configuration variables will be deprecated in a future release. Please set credentials using a connection instead.
  send_mime_email(e_from=mail_from, e_to=recipients, mime_msg=msg, conn_id=conn_id, dryrun=dryrun)

[2025-05-16, 18:05:23 UTC] {configuration.py:1076} WARNING - section/key [smtp/smtp_user] not found in config
[2025-05-16, 18:05:23 UTC] {email.py:272} INFO - Email alerting: attempt 1
[2025-05-16, 18:05:23 UTC] {email.py:283} INFO - Sent an alert email to ['gudv-network-curation-dev@verizon.com']
[2025-05-16, 18:05:23 UTC] {taskinstance.py:340} ▶ Post task execution logs
